Workbook

Sheet HIPER
A2: ALIMENTACION - HIPER PRECOZ / GRANAZZO
A4: DIA | B4: PESO ANIMAL | C4: AUMENTO PESO PROMEDIO | D4: RACION (%) - (PESO) | E4: CANT ALIMENTO (KG)
A6: 1 | B6: 55 | C6: -0.1 | D6: 0.025 | E6: =+B6*D6 -> 1.375
A7: 2 | B7: =+B6+C6 -> 54.9 | C7: -0.1 | D7: 0.025 | E7: =+B7*D7 -> 1.3725
A8: 3 | B8: =+B7+C7 -> 54.8 | C8: -0.1 | D8: 0.025 | E8: =+B8*D8 -> 1.37
A9: 4 | B9: =+B8+C8 -> 54.7 | C9: -0.1 | D9: 0.025 | E9: =+B9*D9 -> 1.3675
A10: 5 | B10: =+B9+C9 -> 54.6 | C10: -0.1 | D10: 0.025 | E10: =+B10*D10 -> 1.365
A11: 6 | B11: =+B10+C10 -> 54.5 | C11: -0.1 | D11: 0.025 | E11: =+B11*D11 -> 1.3625
A12: 7 | B12: =+B11+C11 -> 54.4 | C12: -0.1 | D12: 0.025 | E12: =+B12*D12 -> 1.36
A13: 8 | B13: =+B12+C12 -> 54.3 | C13: 0 | D13: 0.025 | E13: =+B13*D13 -> 1.3575
A14: 9 | B14: =+B13+C13 -> 54.3 | C14: 0.1 | D14: 0.025 | E14: =+B14*D14 -> 1.3575
A15: 10 | B15: =+B14+C14 -> 54.4 | C15: 0.1 | D15: 0.025 | E15: =+B15*D15 -> 1.36
A16: 11 | B16: =+B15+C15 -> 54.5 | C16: 0.1 | D16: 0.025 | E16: =+B16*D16 -> 1.3625
A17: 12 | B17: =+B16+C16 -> 54.6 | C17: 0.15 | D17: 0.025 | E17: =+B17*D17 -> 1.365
A18: 13 | B18: =+B17+C17 -> 54.75 | C18: 0.15 | D18: 0.025 | E18: =+B18*D18 -> 1.36875
... A20: 15 | B20: =+B19+C19 -> 55.05 | C20: 0.15 | D20: 0.025 | E20: =+B20*D20 -> 1.37625
D22: SUBTOTOTAL X TERNERO | E22: =SUM(E6:E21) -> 20.4925
D23: PROMEDIO DIARIO | E23: =AVERAGE(E6:E20) -> 1.3661667
D25: Costo del Alimento (kg) | E25: =PRECOZ!I145/1000 -> 833.86
D27: Costo del procedo de engorde | E27: =+E25*E22 -> 17087.876
D28: Aumento de Kg | E28: =B20-B6 -> 0.05
D29: Precio del Kg de Ternero | E29: 7600
D30: Ganancia por Aumento de Kg | E30: =+E29*E28 -> 380

Sheet PRECOZ
A2: ALIMENTACION - PRECOZ
A4: DIA | B4: PESO ANIMAL | C4: AUMENTO PESO DIARIO | D4: RACION | E4: CANT ALIMENTO
A6: 16 | B6: =+HIPER!B20 -> 55.05 | C6: 0.25 | D6: 0.025 | E6: =+B6*D6 -> 1.37625
A7: 17 | B7: =+B6+C6 -> 55.3 | C7: 0.25 | D7: 0.025 | E7: =+B7*D7 -> 1.3825
A8: 18 | B8: =+B7+C7 -> 55.55 | C8: 0.25 | D8: 0.025 | E8: =+B8*D8 -> 1.38875
A9: 19 | B9: =+B8+C8 -> 55.8 | C9: 0.3 | D9: 0.025 | E9: =+B9*D9 -> 1.395
A10: 20 | B10: =+B9+C9 -> 56.1 | C10: 0.3 | D10: 0.025 | E10: =+B10*D10 -> 1.4025
A11: 21 | B11: =+B10+C10 -> 56.4 | C11: 0.3 | D11: 0.025 | E11: =+B11*D11 -> 1.41
A12: 22 | B12: =+B11+C11 -> 56.7 | C12: 0.3 | D12: 0.025 | E12: =+B12*D12 -> 1.4175
A13: 23 | B13: =+B12+C12 -> 57 | C13: 0.3 | D13: 0.025 | E13: =+B13*D13 -> 1.425
A14: 24 | B14: =+B13+C13 -> 57.3 | C14: 0.3 | D14: 0.025 | E14: =+B14*D14 -> 1.4325
A15: 25 | B15: =+B14+C14 -> 57.6 | C15: 0.3 | D15: 0.025 | E15: =+B15*D15 -> 1.44
A16: 26 | B16: =+B15+C15 -> 57.9 | C16: 0.4 | D16: 0.025 | E16: =+B16*D16 -> 1.4475
A17: 27 | B17: =+B16+C16 -> 58.3 | C17: 0.4 | D17: 0.025 | E17: =+B17*D17 -> 1.4575
A18: 28 | B18: =+B17+C17 -> 58.7 | C18: 0.4 | D18: 0.025 | E18: =+B18*D18 -> 1.4675
... A140: 150 | B140: =+B139+C139 -> 132 | C140: 0.7 | D140: 0.03 | E140: =+B140*D140 -> 3.96
D143: SUBTOTAL X TERNERO (KG) | E143: =SUM(E6:E142) -> 355.69
D144: PROMEDIO | E144: =AVERAGE(E6:E140) -> 2.6347407
H145: Destete Hiperprecoz 23 % - Tonelada | I145: =19717.5*40+45160 -> 833860
D146: Costo del Alimento (kg) | E146: =+I146/1000 -> 509.36 | H146: Destete Precoz 19 % - Tonelada | I146: =464200+45160 -> 509360
H147: Vacuno Recria 16 % - Tonelada | I147: =412000+45160 -> 457160
D148: Costo del procedo de engorde | E148: =+E146*E143 -> 181174.26 | H148: Suplemento mineral Rodeo General - Tonelada | I148: =610300+45160 -> 655460
D149: Aumento de Kg | E149: =+B140-B6 -> 76.95
D150: Precio del Kg de Ternero | E150: 7000
D151: Ganancia por Aumento de Kg | E151: =+E150*E149 -> 538650
D153: Resultado del Proceso | E153: =+E151-E148 -> 357475.74

Sheet RESUMEN
A2: ALLIMENTACION - GRANAZZO
A4: ALIMENTO | B4: COSTO | C4: HIPER | E4: PRECOZ (KG) | G4: SUBTOTAL | H4: SAL (KG)
A5: TERNEROS | C5: KG | D5: BOLSAS (25 KG) | E5: KG | F5: BOLSAS (30 KG) | H5: KG | I5: BOLSAS (25 KG)
A6: 1 | C6: =+HIPER!E22 -> 20.4925 | D6: =+C6/MID($D$5,9,2) -> 0.8197 | E6: =+PRECOZ!E143 -> 355.69 | F6: =+E6/MID($F$5,9,2) -> 11.856333 | G6: =+C6+E6 -> 376.1825 | H6: 900 | I6: =+H6/MID($I$5,9,2) -> 36
A7: 230 | C7: =+A7*C6 -> 4713.275 | D7: =+C7/MID($D$5,9,2) -> 188.531 | E7: =+A7*E6 -> 81808.7 | F7: =+E7/MID($F$5,9,2) -> 2726.9567 | G7: =+C7+E7 -> 86521.975
A8: TN | C8: =+C7/1000 -> 4.713275 | E8: =+E7/1000 -> 81.8087

Sheet SEGUIMIENTO
A2: ALIMENTACION - SEGUIMIENTO / GRANAZZO
A4: LOTE 1 - 33 TERNEROS
F5: HIPER | I5: PRECOZ
A6: DIA | B6: PESO ANIMAL (KG) | C6: TERNEROS CANTIDAD | D6: AUMENTO PESO PROMEDIO | E6: RACION (%) - (PESO) | F6: CANT ALIMENTO (KG) | G6: CANT ALIMENTO DIARIO ACUMULADO | H6: CANT BOLSAS DIARIAS | I6: CANT ALIMENTO DIARIO (KG) | J6: CANT ALIMENTO ACUMULADO | K6: CANT BOLSAS DIARIAS
A9: 45952 | B9: =+HIPER!B6 -> 55 | D9: =+HIPER!C6 -> -0.1 | E9: =+HIPER!D6 -> 0.025 | F9: =(B9*E9)*C9 -> 0 | G9: =+F9 -> 0 | H9: =+MROUND(F9/25,0.5) -> 0
A10: =+A9+1 -> 45953 | B10: =+B9+D9 -> 54.9 | C10: =+C9 -> 0 | D10: =+HIPER!C7 -> -0.1 | E10: =+HIPER!D7 -> 0.025 | F10: =(B10*E10)*C10 -> 0 | G10: =+F10+G9 -> 0 | H10: =+MROUND(F10/25,0.5) -> 0
A11: =+A10+1 -> 45954 | B11: =+B10+D10 -> 54.8 | C11: =+C10 -> 0 | D11: =+HIPER!C8 -> -0.1 | E11: =+HIPER!D8 -> 0.025 | F11: =(B11*E11)*C11 -> 0 | G11: =+F11+G10 -> 0 | H11: =+MROUND(F11/25,0.5) -> 0
A12: =+A11+1 -> 45955 | B12: =+B11+D11 -> 54.7 | C12: =+C11 -> 0 | D12: =+HIPER!C9 -> -0.1 | E12: =+HIPER!D9 -> 0.025 | F12: =(B12*E12)*C12 -> 0 | G12: =+F12+G11 -> 0 | H12: =+MROUND(F12/25,0.5) -> 0
A13: =+A12+1 -> 45956 | B13: =+B12+D12 -> 54.6 | C13: =+C12 -> 0 | D13: =+HIPER!C10 -> -0.1 | E13: =+HIPER!D10 -> 0.025 | F13: =(B13*E13)*C13 -> 0 | G13: =+F13+G12 -> 0 | H13: =+MROUND(F13/25,0.5) -> 0
A14: =+A13+1 -> 45957 | B14: =+B13+D13 -> 54.5 | C14: =+C13 -> 0 | D14: =+HIPER!C11 -> -0.1 | E14: =+HIPER!D11 -> 0.025 | F14: =(B14*E14)*C14 -> 0 | G14: =+F14+G13 -> 0 | H14: =+MROUND(F14/25,0.5) -> 0
A15: =+A14+1 -> 45958 | B15: =+B14+D14 -> 54.4 | C15: =+C14 -> 0 | D15: =+HIPER!C12 -> -0.1 | E15: =+HIPER!D12 -> 0.025 | F15: =(B15*E15)*C15 -> 0 | G15: =+F15+G14 -> 0 | H15: =+MROUND(F15/25,0.5) -> 0
A16: =+A15+1 -> 45959 | B16: =+B15+D15 -> 54.3 | C16: =+C15 -> 0 | D16: =+HIPER!C13 -> 0 | E16: =+HIPER!D13 -> 0.025 | F16: =(B16*E16)*C16 -> 0 | G16: =+F16+G15 -> 0 | H16: =+MROUND(F16/25,0.5) -> 0
A17: =+A16+1 -> 45960 | B17: =+B16+D16 -> 54.3 | C17: =+C16 -> 0 | D17: =+HIPER!C14 -> 0.1 | E17: =+HIPER!D14 -> 0.025 | F17: =(B17*E17)*C17 -> 0 | G17: =+F17+G16 -> 0 | H17: =+MROUND(F17/25,0.5) -> 0
A18: =+A17+1 -> 45961 | B18: =+B17+D17 -> 54.4 | C18: =+C17 -> 0 | D18: =+HIPER!C15 -> 0.1 | E18: =+HIPER!D15 -> 0.025 | F18: =(B18*E18)*C18 -> 0 | G18: =+F18+G17 -> 0 | H18: =+MROUND(F18/25,0.5) -> 0
A19: =+A18+1 -> 45962 | B19: =+B18+D18 -> 54.5 | C19: =+C18 -> 0 | D19: =+HIPER!C16 -> 0.1 | E19: =+HIPER!D16 -> 0.025 | F19: =(B19*E19)*C19 -> 0 | G19: =+F19+G18 -> 0 | H19: =+MROUND(F19/25,0.5) -> 0
A20: =+A19+1 -> 45963 | B20: =+B19+D19 -> 54.6 | C20: =+C19 -> 0 | D20: =+HIPER!C17 -> 0.15 | E20: =+HIPER!D17 -> 0.025 | F20: =(B20*E20)*C20 -> 0 | G20: =+F20+G19 -> 0 | H20: =+MROUND(F20/25,0.5) -> 0
A21: =+A20+1 -> 45964 | B21: =+B20+D20 -> 54.75 | C21: =+C20 -> 0 | D21: =+HIPER!C18 -> 0.15 | E21: =+HIPER!D18 -> 0.025 | F21: =(B21*E21)*C21 -> 0 | G21: =+F21+G20 -> 0 | H21: =+MROUND(F21/25,0.5) -> 0
... A23: =+A22+1 -> 45966 | B23: =+B22+D22 -> 55.05 | C23: =+C22 -> 0 | D23: =+HIPER!C20 -> 0.15 | E23: =+HIPER!D20 -> 0.025 | F23: =(B23*E23)*C23 -> 0 | G23: =+F23+G22 -> 0 | H23: =+MROUND(F23/25,0.5) -> 0
A24: =+A23+1 -> 45967 | B24: =+B23+D23 -> 55.2 | C24: =+C23 -> 0 | D24: =+PRECOZ!C6 -> 0.25 | E24: =+PRECOZ!D6 -> 0.025 | I24: =+B24*E24*C24 -> 0 | J24: =+I24 -> 0 | K24: =+MROUND(I24/30,0.5) -> 0
A25: =+A24+1 -> 45968 | B25: =+B24+D24 -> 55.45 | C25: =+C24 -> 0 | D25: =+PRECOZ!C7 -> 0.25 | E25: =+PRECOZ!D7 -> 0.025 | I25: =+B25*E25*C25 -> 0 | J25: =+I25+J24 -> 0 | K25: =+MROUND(I25/30,0.5) -> 0
A26: =+A25+1 -> 45969 | B26: =+B25+D25 -> 55.7 | C26: =+C25 -> 0 | D26: =+PRECOZ!C8 -> 0.25 | E26: =+PRECOZ!D8 -> 0.025 | I26: =+B26*E26*C26 -> 0 | J26: =+I26+J25 -> 0 | K26: =+MROUND(I26/30,0.5) -> 0
A27: =+A26+1 -> 45970 | B27: =+B26+D26 -> 55.95 | C27: =+C26 -> 0 | D27: =+PRECOZ!C9 -> 0.3 | E27: =+PRECOZ!D9 -> 0.025 | I27: =+B27*E27*C27 -> 0 | J27: =+I27+J26 -> 0 | K27: =+MROUND(I27/30,0.5) -> 0
A28: =+A27+1 -> 45971 | B28: =+B27+D27 -> 56.25 | C28: =+C27 -> 0 | D28: =+PRECOZ!C10 -> 0.3 | E28: =+PRECOZ!D10 -> 0.025 | I28: =+B28*E28*C28 -> 0 | J28: =+I28+J27 -> 0 | K28: =+MROUND(I28/30,0.5) -> 0
A29: =+A28+1 -> 45972 | B29: =+B28+D28 -> 56.55 | C29: =+C28 -> 0 | D29: =+PRECOZ!C11 -> 0.3 | E29: =+PRECOZ!D11 -> 0.025 | I29: =+B29*E29*C29 -> 0 | J29: =+I29+J28 -> 0 | K29: =+MROUND(I29/30,0.5) -> 0
A30: =+A29+1 -> 45973 | B30: =+B29+D29 -> 56.85 | C30: =+C29 -> 0 | D30: =+PRECOZ!C12 -> 0.3 | E30: =+PRECOZ!D12 -> 0.025 | I30: =+B30*E30*C30 -> 0 | J30: =+I30+J29 -> 0 | K30: =+MROUND(I30/30,0.5) -> 0
A31: =+A30+1 -> 45974 | B31: =+B30+D30 -> 57.15 | C31: =+C30 -> 0 | D31: =+PRECOZ!C13 -> 0.3 | E31: =+PRECOZ!D13 -> 0.025 | I31: =+B31*E31*C31 -> 0 | J31: =+I31+J30 -> 0 | K31: =+MROUND(I31/30,0.5) -> 0
A32: =+A31+1 -> 45975 | B32: =+B31+D31 -> 57.45 | C32: =+C31 -> 0 | D32: =+PRECOZ!C14 -> 0.3 | E32: =+PRECOZ!D14 -> 0.025 | I32: =+B32*E32*C32 -> 0 | J32: =+I32+J31 -> 0 | K32: =+MROUND(I32/30,0.5) -> 0
A33: =+A32+1 -> 45976 | B33: =+B32+D32 -> 57.75 | C33: =+C32 -> 0 | D33: =+PRECOZ!C15 -> 0.3 | E33: =+PRECOZ!D15 -> 0.025 | I33: =+B33*E33*C33 -> 0 | J33: =+I33+J32 -> 0 | K33: =+MROUND(I33/30,0.5) -> 0
A34: =+A33+1 -> 45977 | B34: =+B33+D33 -> 58.05 | C34: =+C33 -> 0 | D34: =+PRECOZ!C16 -> 0.4 | E34: =+PRECOZ!D16 -> 0.025 | I34: =+B34*E34*C34 -> 0 | J34: =+I34+J33 -> 0 | K34: =+MROUND(I34/30,0.5) -> 0
A35: =+A34+1 -> 45978 | B35: =+B34+D34 -> 58.45 | C35: =+C34 -> 0 | D35: =+PRECOZ!C17 -> 0.4 | E35: =+PRECOZ!D17 -> 0.025 | I35: =+B35*E35*C35 -> 0 | J35: =+I35+J34 -> 0 | K35: =+MROUND(I35/30,0.5) -> 0
A36: =+A35+1 -> 45979 | B36: =+B35+D35 -> 58.85 | D36: =+PRECOZ!C18 -> 0.4 | E36: =+PRECOZ!D18 -> 0.025 | I36: =+B36*E36*C36 -> 0 | J36: =+I36+J35 -> 0 | K36: =+MROUND(I36/30,0.5) -> 0
A37: =+A36+1 -> 45980 | B37: =+B36+D36 -> 59.25 | C37: =+RESUMEN!A7 -> 230 | D37: =+PRECOZ!C19 -> 0.4 | E37: =+PRECOZ!D19 -> 0.025 | I37: =+B37*E37*C37 -> 340.6875 | J37: =+I37+J36 -> 340.6875 | K37: =+MROUND(I37/30,0.5) -> 11.5
A38: =+A37+1 -> 45981 | B38: =+B37+D37 -> 59.65 | C38: =+C37 -> 230 | D38: =+PRECOZ!C20 -> 0.4 | E38: =+PRECOZ!D20 -> 0.025 | I38: =+B38*E38*C38 -> 342.9875 | J38: =+I38+J37 -> 683.675 | K38: =+MROUND(I38/30,0.5) -> 11.5
A39: =+A38+1 -> 45982 | B39: =+B38+D38 -> 60.05 | C39: =+C38 -> 230 | D39: =+PRECOZ!C21 -> 0.4 | E39: =+PRECOZ!D21 -> 0.03 | I39: =+B39*E39*C39 -> 414.345 | J39: =+I39+J38 -> 1098.02 | K39: =+MROUND(I39/30,0.5) -> 14
A40: =+A39+1 -> 45983 | B40: =+B39+D39 -> 60.45 | C40: =+C39 -> 230 | D40: =+PRECOZ!C22 -> 0.4 | E40: =+PRECOZ!D22 -> 0.03 | I40: =+B40*E40*C40 -> 417.105 | J40: =+I40+J39 -> 1515.125 | K40: =+MROUND(I40/30,0.5) -> 14
A41: =+A40+1 -> 45984 | B41: =+B40+D40 -> 60.85 | C41: =+C40 -> 230 | D41: =+PRECOZ!C23 -> 0.4 | E41: =+PRECOZ!D23 -> 0.03 | I41: =+B41*E41*C41 -> 419.865 | J41: =+I41+J40 -> 1934.99 | K41: =+MROUND(I41/30,0.5) -> 14
A42: =+A41+1 -> 45985 | B42: =+B41+D41 -> 61.25 | C42: =+C41 -> 230 | D42: =+PRECOZ!C24 -> 0.4 | E42: =+PRECOZ!D24 -> 0.03 | I42: =+B42*E42*C42 -> 422.625 | J42: =+I42+J41 -> 2357.615 | K42: =+MROUND(I42/30,0.5) -> 14
A43: =+A42+1 -> 45986 | B43: =+B42+D42 -> 61.65 | C43: =+C42 -> 230 | D43: =+PRECOZ!C25 -> 0.4 | E43: =+PRECOZ!D25 -> 0.03 | I43: =+B43*E43*C43 -> 425.385 | J43: =+I43+J42 -> 2783 | K43: =+MROUND(I43/30,0.5) -> 14
A44: =+A43+1 -> 45987 | B44: =+B43+D43 -> 62.05 | C44: =+C43 -> 230 | D44: =+PRECOZ!C26 -> 0.4 | E44: =+PRECOZ!D26 -> 0.03 | I44: =+B44*E44*C44 -> 428.145 | J44: =+I44+J43 -> 3211.145 | K44: =+MROUND(I44/30,0.5) -> 14.5
A45: =+A44+1 -> 45988 | B45: =+B44+D44 -> 62.45 | C45: =+C44 -> 230 | D45: =+PRECOZ!C27 -> 0.4 | E45: =+PRECOZ!D27 -> 0.03 | I45: =+B45*E45*C45 -> 430.905 | J45: =+I45+J44 -> 3642.05 | K45: =+MROUND(I45/30,0.5) -> 14.5
...

Sheet VARIABLES MODELO
A1: VARIABLES GLOBALES - DESTETE CARAVANA CELESTE
A3: Variable | B3: Valor | C3: Unidad | D3: Observación
A4: Fecha inicio destete | B4: 46285 | C4: fecha | D4: Primer lote - caravana Celeste
A5: Cantidad de terneros | B5: 33 | C5: cabezas | D5: Caravanas Celestes
A6: Peso inicial | B6: 55 | C6: kg/cab | D6: Promedio del pesaje
A7: Precio Hiper-Precoz 23% p/Tn | B7: 833860 | C7: $/ton | D7: Según Cotización XXXXXX - Fecha xx/xx/xx
A8: Precio Hiper-Precoz 23% p/kg | B8: =B7/1000 -> 833.86 | C8: $/kg
A9: Precio Precoz 19% p/Tn | B9: 509360 | C9: $/ton | D9: Según Cotización XXXXXX - Fecha xx/xx/xx
A10: Precio Precoz 19% p/kg | B10: =B9/1000 -> 509.36 | C10: $/kg
A11: Peso de la Bolsa Hiper-Precoz | B11: 25 | C11: kg/bolsa | D11: Según Proveedor
A12: Peso de la Bolsa Precoz | B12: 30 | C12: kg/bolsa | D12: Según Proveedor
A13: Consumo % PV días 1-5 | B13: 0.02 | C13: % PV
A14: Consumo % PV días 6-15 | B14: 0.035 | C14: % PV
A15: Consumo % PV días 16-50 | B15: 0.032 | C15: % PV
A16: Consumo % PV días 51-80 | B16: 0.03 | C16: % PV
A17: Consumo % PV días 81-120 | B17: 0.028 | C17: % PV
A18: Consumo % PV días 120-150 | B18: 0.025 | C18: % PV
A19: Precio kg ternero | B19: 7000 | C19: $/kg PV | D19: Estimado a la fecha de venta
A20: Costo alfalfa por kg | B20: 0 | C20: $/kg
A21: Consumo alfalfa kg/cab/día | B21: 0 | C21: kg/cab/día

Sheet MODELO 150D
A1: MODELO DINÁMICO 150 DÍAS - LOTE CELESTE
A3: Día | B3: Fecha | C3: Fase | D3: Peso teórico kg | E3: ADPV kg/d | F3: Consumo % PV | G3: Ración teórica kg/cab | H3: Consumo real kg/cab | I3: Consumo usado kg/cab | J3: Costo $/kg | K3: Costo diario $/cab | L3: Costo acum. $/cab | M3: Alimento lote kg | N3: Bolsas Diarias | O3: Bolsas acum. | P3: Observación
A4: 1 | B4: ='VARIABLES MODELO'!$B$4+A4-1 -> 46285 | C4: =IF(A4<=15,"Hiper-Precoz 23%","Precoz 19%") -> Hiper-Precoz 23% | D4: =+'VARIABLES MODELO'!B6 -> 55 | E4: =HIPER!C6 -> -0.1 | F4: =IF(A4<=5,'VARIABLES MODELO'!$B$13,IF(A4<=15,'VARIABLES MODELO'!$B$14,IF(A4<=50,'VARIABLES MODELO'!$B$15,IF(A4<=80,'VARIABLES MODELO'!$B$16,IF(A4<=120,'VARIABLES MODELO'!$B$17,'VARIABLES MODELO'!$B$18))))) -> 0.02 | G4: =D4*F4 -> 1.1 | I4: =IF(H4="",G4,H4) -> 1.1 | J4: =IF(A4<=15,'VARIABLES MODELO'!$B$8,'VARIABLES MODELO'!$B$10) -> 833.86 | K4: =I4*J4 -> 917.246 | L4: =SUM($K$4:K4) -> 917.246 | M4: =MROUND(I4*'VARIABLES MODELO'!$B$5,25) -> 25 | N4: =IF(A4<=15,MROUND(M4/'VARIABLES MODELO'!$B$11,0.5),MROUND(M4/'VARIABLES MODELO'!$B$12,0.5)) -> 1 | O4: =IF(A4<=15,SUM($M$4:M4)/'VARIABLES MODELO'!$B$11,SUM($M4:M$19)/'VARIABLES MODELO'!$B$12) -> 1
A5: 2 | B5: ='VARIABLES MODELO'!$B$4+A5-1 -> 46286 | C5: =IF(A5<=15,"Hiper-Precoz 23%","Precoz 19%") -> Hiper-Precoz 23% | D5: =+D4+E4 -> 54.9 | E5: =HIPER!C7 -> -0.1 | F5: =IF(A5<=5,'VARIABLES MODELO'!$B$13,IF(A5<=15,'VARIABLES MODELO'!$B$14,IF(A5<=50,'VARIABLES MODELO'!$B$15,IF(A5<=80,'VARIABLES MODELO'!$B$16,IF(A5<=120,'VARIABLES MODELO'!$B$17,'VARIABLES MODELO'!$B$18))))) -> 0.02 | G5: =D5*F5 -> 1.098 | I5: =IF(H5="",G5,H5) -> 1.098 | J5: =IF(A5<=15,'VARIABLES MODELO'!$B$8,'VARIABLES MODELO'!$B$10) -> 833.86 | K5: =I5*J5 -> 915.57828 | L5: =SUM($K$4:K5) -> 1832.8243 | M5: =MROUND(I5*'VARIABLES MODELO'!$B$5,25) -> 25 | N5: =IF(A5<=15,MROUND(M5/'VARIABLES MODELO'!$B$11,0.5),MROUND(M5/'VARIABLES MODELO'!$B$12,0.5)) -> 1 | O5: =IF(A5<=15,SUM($M$4:M5)/'VARIABLES MODELO'!$B$11,SUM($M5:M$19)/'VARIABLES MODELO'!$B$12) -> 2
A6: 3 | B6: ='VARIABLES MODELO'!$B$4+A6-1 -> 46287 | C6: =IF(A6<=15,"Hiper-Precoz 23%","Precoz 19%") -> Hiper-Precoz 23% | D6: =+D5+E5 -> 54.8 | E6: =HIPER!C8 -> -0.1 | F6: =IF(A6<=5,'VARIABLES MODELO'!$B$13,IF(A6<=15,'VARIABLES MODELO'!$B$14,IF(A6<=50,'VARIABLES MODELO'!$B$15,IF(A6<=80,'VARIABLES MODELO'!$B$16,IF(A6<=120,'VARIABLES MODELO'!$B$17,'VARIABLES MODELO'!$B$18))))) -> 0.02 | G6: =D6*F6 -> 1.096 | I6: =IF(H6="",G6,H6) -> 1.096 | J6: =IF(A6<=15,'VARIABLES MODELO'!$B$8,'VARIABLES MODELO'!$B$10) -> 833.86 | K6: =I6*J6 -> 913.91056 | L6: =SUM($K$4:K6) -> 2746.7348 | M6: =MROUND(I6*'VARIABLES MODELO'!$B$5,25) -> 25 | N6: =IF(A6<=15,MROUND(M6/'VARIABLES MODELO'!$B$11,0.5),MROUND(M6/'VARIABLES MODELO'!$B$12,0.5)) -> 1 | O6: =IF(A6<=15,SUM($M$4:M6)/'VARIABLES MODELO'!$B$11,SUM($M6:M$19)/'VARIABLES MODELO'!$B$12) -> 3
A7: 4 | B7: ='VARIABLES MODELO'!$B$4+A7-1 -> 46288 | C7: =IF(A7<=15,"Hiper-Precoz 23%","Precoz 19%") -> Hiper-Precoz 23% | D7: =+D6+E6 -> 54.7 | E7: =HIPER!C9 -> -0.1 | F7: =IF(A7<=5,'VARIABLES MODELO'!$B$13,IF(A7<=15,'VARIABLES MODELO'!$B$14,IF(A7<=50,'VARIABLES MODELO'!$B$15,IF(A7<=80,'VARIABLES MODELO'!$B$16,IF(A7<=120,'VARIABLES MODELO'!$B$17,'VARIABLES MODELO'!$B$18))))) -> 0.02 | G7: =D7*F7 -> 1.094 | I7: =IF(H7="",G7,H7) -> 1.094 | J7: =IF(A7<=15,'VARIABLES MODELO'!$B$8,'VARIABLES MODELO'!$B$10) -> 833.86 | K7: =I7*J7 -> 912.24284 | L7: =SUM($K$4:K7) -> 3658.9777 | M7: =MROUND(I7*'VARIABLES MODELO'!$B$5,25) -> 25 | N7: =IF(A7<=15,MROUND(M7/'VARIABLES MODELO'!$B$11,0.5),MROUND(M7/'VARIABLES MODELO'!$B$12,0.5)) -> 1 | O7: =IF(A7<=15,SUM($M$4:M7)/'VARIABLES MODELO'!$B$11,SUM($M7:M$19)/'VARIABLES MODELO'!$B$12) -> 4
A8: 5 | B8: ='VARIABLES MODELO'!$B$4+A8-1 -> 46289 | C8: =IF(A8<=15,"Hiper-Precoz 23%","Precoz 19%") -> Hiper-Precoz 23% | D8: =+D7+E7 -> 54.6 | E8: =HIPER!C10 -> -0.1 | F8: =IF(A8<=5,'VARIABLES MODELO'!$B$13,IF(A8<=15,'VARIABLES MODELO'!$B$14,IF(A8<=50,'VARIABLES MODELO'!$B$15,IF(A8<=80,'VARIABLES MODELO'!$B$16,IF(A8<=120,'VARIABLES MODELO'!$B$17,'VARIABLES MODELO'!$B$18))))) -> 0.02 | G8: =D8*F8 -> 1.092 | I8: =IF(H8="",G8,H8) -> 1.092 | J8: =IF(A8<=15,'VARIABLES MODELO'!$B$8,'VARIABLES MODELO'!$B$10) -> 833.86 | K8: =I8*J8 -> 910.57512 | L8: =SUM($K$4:K8) -> 4569.5528 | M8: =MROUND(I8*'VARIABLES MODELO'!$B$5,25) -> 25 | N8: =IF(A8<=15,MROUND(M8/'VARIABLES MODELO'!$B$11,0.5),MROUND(M8/'VARIABLES MODELO'!$B$12,0.5)) -> 1 | O8: =IF(A8<=15,SUM($M$4:M8)/'VARIABLES MODELO'!$B$11,SUM($M8:M$19)/'VARIABLES MODELO'!$B$12) -> 5
A9: 6 | B9: ='VARIABLES MODELO'!$B$4+A9-1 -> 46290 | C9: =IF(A9<=15,"Hiper-Precoz 23%","Precoz 19%") -> Hiper-Precoz 23% | D9: =+D8+E8 -> 54.5 | E9: =HIPER!C11 -> -0.1 | F9: =IF(A9<=5,'VARIABLES MODELO'!$B$13,IF(A9<=15,'VARIABLES MODELO'!$B$14,IF(A9<=50,'VARIABLES MODELO'!$B$15,IF(A9<=80,'VARIABLES MODELO'!$B$16,IF(A9<=120,'VARIABLES MODELO'!$B$17,'VARIABLES MODELO'!$B$18))))) -> 0.035 | G9: =D9*F9 -> 1.9075 | I9: =IF(H9="",G9,H9) -> 1.9075 | J9: =IF(A9<=15,'VARIABLES MODELO'!$B$8,'VARIABLES MODELO'!$B$10) -> 833.86 | K9: =I9*J9 -> 1590.588 | L9: =SUM($K$4:K9) -> 6160.1407 | M9: =MROUND(I9*'VARIABLES MODELO'!$B$5,25) -> 75 | N9: =IF(A9<=15,MROUND(M9/'VARIABLES MODELO'!$B$11,0.5),MROUND(M9/'VARIABLES MODELO'!$B$12,0.5)) -> 3 | O9: =IF(A9<=15,SUM($M$4:M9)/'VARIABLES MODELO'!$B$11,SUM($M9:M$19)/'VARIABLES MODELO'!$B$12) -> 8
A10: 7 | B10: ='VARIABLES MODELO'!$B$4+A10-1 -> 46291 | C10: =IF(A10<=15,"Hiper-Precoz 23%","Precoz 19%") -> Hiper-Precoz 23% | D10: =+D9+E9 -> 54.4 | E10: =HIPER!C12 -> -0.1 | F10: =IF(A10<=5,'VARIABLES MODELO'!$B$13,IF(A10<=15,'VARIABLES MODELO'!$B$14,IF(A10<=50,'VARIABLES MODELO'!$B$15,IF(A10<=80,'VARIABLES MODELO'!$B$16,IF(A10<=120,'VARIABLES MODELO'!$B$17,'VARIABLES MODELO'!$B$18))))) -> 0.035 | G10: =D10*F10 -> 1.904 | I10: =IF(H10="",G10,H10) -> 1.904 | J10: =IF(A10<=15,'VARIABLES MODELO'!$B$8,'VARIABLES MODELO'!$B$10) -> 833.86 | K10: =I10*J10 -> 1587.6694 | L10: =SUM($K$4:K10) -> 7747.8102 | M10: =MROUND(I10*'VARIABLES MODELO'!$B$5,25) -> 75 | N10: =IF(A10<=15,MROUND(M10/'VARIABLES MODELO'!$B$11,0.5),MROUND(M10/'VARIABLES MODELO'!$B$12,0.5)) -> 3 | O10: =IF(A10<=15,SUM($M$4:M10)/'VARIABLES MODELO'!$B$11,SUM($M10:M$19)/'VARIABLES MODELO'!$B$12) -> 11
A11: 8 | B11: ='VARIABLES MODELO'!$B$4+A11-1 -> 46292 | C11: =IF(A11<=15,"Hiper-Precoz 23%","Precoz 19%") -> Hiper-Precoz 23% | D11: =+D10+E10 -> 54.3 | E11: =HIPER!C13 -> 0 | F11: =IF(A11<=5,'VARIABLES MODELO'!$B$13,IF(A11<=15,'VARIABLES MODELO'!$B$14,IF(A11<=50,'VARIABLES MODELO'!$B$15,IF(A11<=80,'VARIABLES MODELO'!$B$16,IF(A11<=120,'VARIABLES MODELO'!$B$17,'VARIABLES MODELO'!$B$18))))) -> 0.035 | G11: =D11*F11 -> 1.9005 | I11: =IF(H11="",G11,H11) -> 1.9005 | J11: =IF(A11<=15,'VARIABLES MODELO'!$B$8,'VARIABLES MODELO'!$B$10) -> 833.86 | K11: =I11*J11 -> 1584.7509 | L11: =SUM($K$4:K11) -> 9332.5611 | M11: =MROUND(I11*'VARIABLES MODELO'!$B$5,25) -> 75 | N11: =IF(A11<=15,MROUND(M11/'VARIABLES MODELO'!$B$11,0.5),MROUND(M11/'VARIABLES MODELO'!$B$12,0.5)) -> 3 | O11: =IF(A11<=15,SUM($M$4:M11)/'VARIABLES MODELO'!$B$11,SUM($M11:M$19)/'VARIABLES MODELO'!$B$12) -> 14
A12: 9 | B12: ='VARIABLES MODELO'!$B$4+A12-1 -> 46293 | C12: =IF(A12<=15,"Hiper-Precoz 23%","Precoz 19%") -> Hiper-Precoz 23% | D12: =+D11+E11 -> 54.3 | E12: =HIPER!C14 -> 0.1 | F12: =IF(A12<=5,'VARIABLES MODELO'!$B$13,IF(A12<=15,'VARIABLES MODELO'!$B$14,IF(A12<=50,'VARIABLES MODELO'!$B$15,IF(A12<=80,'VARIABLES MODELO'!$B$16,IF(A12<=120,'VARIABLES MODELO'!$B$17,'VARIABLES MODELO'!$B$18))))) -> 0.035 | G12: =D12*F12 -> 1.9005 | I12: =IF(H12="",G12,H12) -> 1.9005 | J12: =IF(A12<=15,'VARIABLES MODELO'!$B$8,'VARIABLES MODELO'!$B$10) -> 833.86 | K12: =I12*J12 -> 1584.7509 | L12: =SUM($K$4:K12) -> 10917.312 | M12: =MROUND(I12*'VARIABLES MODELO'!$B$5,25) -> 75 | N12: =IF(A12<=15,MROUND(M12/'VARIABLES MODELO'!$B$11,0.5),MROUND(M12/'VARIABLES MODELO'!$B$12,0.5)) -> 3 | O12: =IF(A12<=15,SUM($M$4:M12)/'VARIABLES MODELO'!$B$11,SUM($M12:M$19)/'VARIABLES MODELO'!$B$12) -> 17
A13: 10 | B13: ='VARIABLES MODELO'!$B$4+A13-1 -> 46294 | C13: =IF(A13<=15,"Hiper-Precoz 23%","Precoz 19%") -> Hiper-Precoz 23% | D13: =+D12+E12 -> 54.4 | E13: =HIPER!C15 -> 0.1 | F13: =IF(A13<=5,'VARIABLES MODELO'!$B$13,IF(A13<=15,'VARIABLES MODELO'!$B$14,IF(A13<=50,'VARIABLES MODELO'!$B$15,IF(A13<=80,'VARIABLES MODELO'!$B$16,IF(A13<=120,'VARIABLES MODELO'!$B$17,'VARIABLES MODELO'!$B$18))))) -> 0.035 | G13: =D13*F13 -> 1.904 | I13: =IF(H13="",G13,H13) -> 1.904 | J13: =IF(A13<=15,'VARIABLES MODELO'!$B$8,'VARIABLES MODELO'!$B$10) -> 833.86 | K13: =I13*J13 -> 1587.6694 | L13: =SUM($K$4:K13) -> 12504.981 | M13: =MROUND(I13*'VARIABLES MODELO'!$B$5,25) -> 75 | N13: =IF(A13<=15,MROUND(M13/'VARIABLES MODELO'!$B$11,0.5),MROUND(M13/'VARIABLES MODELO'!$B$12,0.5)) -> 3 | O13: =IF(A13<=15,SUM($M$4:M13)/'VARIABLES MODELO'!$B$11,SUM($M13:M$19)/'VARIABLES MODELO'!$B$12) -> 20
A14: 11 | B14: ='VARIABLES MODELO'!$B$4+A14-1 -> 46295 | C14: =IF(A14<=15,"Hiper-Precoz 23%","Precoz 19%") -> Hiper-Precoz 23% | D14: =+D13+E13 -> 54.5 | E14: =HIPER!C16 -> 0.1 | F14: =IF(A14<=5,'VARIABLES MODELO'!$B$13,IF(A14<=15,'VARIABLES MODELO'!$B$14,IF(A14<=50,'VARIABLES MODELO'!$B$15,IF(A14<=80,'VARIABLES MODELO'!$B$16,IF(A14<=120,'VARIABLES MODELO'!$B$17,'VARIABLES MODELO'!$B$18))))) -> 0.035 | G14: =D14*F14 -> 1.9075 | I14: =IF(H14="",G14,H14) -> 1.9075 | J14: =IF(A14<=15,'VARIABLES MODELO'!$B$8,'VARIABLES MODELO'!$B$10) -> 833.86 | K14: =I14*J14 -> 1590.588 | L14: =SUM($K$4:K14) -> 14095.569 | M14: =MROUND(I14*'VARIABLES MODELO'!$B$5,25) -> 75 | N14: =IF(A14<=15,MROUND(M14/'VARIABLES MODELO'!$B$11,0.5),MROUND(M14/'VARIABLES MODELO'!$B$12,0.5)) -> 3 | O14: =IF(A14<=15,SUM($M$4:M14)/'VARIABLES MODELO'!$B$11,SUM($M14:M$19)/'VARIABLES MODELO'!$B$12) -> 23
A15: 12 | B15: ='VARIABLES MODELO'!$B$4+A15-1 -> 46296 | C15: =IF(A15<=15,"Hiper-Precoz 23%","Precoz 19%") -> Hiper-Precoz 23% | D15: =+D14+E14 -> 54.6 | E15: =HIPER!C17 -> 0.15 | F15: =IF(A15<=5,'VARIABLES MODELO'!$B$13,IF(A15<=15,'VARIABLES MODELO'!$B$14,IF(A15<=50,'VARIABLES MODELO'!$B$15,IF(A15<=80,'VARIABLES MODELO'!$B$16,IF(A15<=120,'VARIABLES MODELO'!$B$17,'VARIABLES MODELO'!$B$18))))) -> 0.035 | G15: =D15*F15 -> 1.911 | I15: =IF(H15="",G15,H15) -> 1.911 | J15: =IF(A15<=15,'VARIABLES MODELO'!$B$8,'VARIABLES MODELO'!$B$10) -> 833.86 | K15: =I15*J15 -> 1593.5065 | L15: =SUM($K$4:K15) -> 15689.076 | M15: =MROUND(I15*'VARIABLES MODELO'!$B$5,25) -> 75 | N15: =IF(A15<=15,MROUND(M15/'VARIABLES MODELO'!$B$11,0.5),MROUND(M15/'VARIABLES MODELO'!$B$12,0.5)) -> 3 | O15: =IF(A15<=15,SUM($M$4:M15)/'VARIABLES MODELO'!$B$11,SUM($M15:M$19)/'VARIABLES MODELO'!$B$12) -> 26
A16: 13 | B16: ='VARIABLES MODELO'!$B$4+A16-1 -> 46297 | C16: =IF(A16<=15,"Hiper-Precoz 23%","Precoz 19%") -> Hiper-Precoz 23% | D16: =+D15+E15 -> 54.75 | E16: =HIPER!C18 -> 0.15 | F16: =IF(A16<=5,'VARIABLES MODELO'!$B$13,IF(A16<=15,'VARIABLES MODELO'!$B$14,IF(A16<=50,'VARIABLES MODELO'!$B$15,IF(A16<=80,'VARIABLES MODELO'!$B$16,IF(A16<=120,'VARIABLES MODELO'!$B$17,'VARIABLES MODELO'!$B$18))))) -> 0.035 | G16: =D16*F16 -> 1.91625 | I16: =IF(H16="",G16,H16) -> 1.91625 | J16: =IF(A16<=15,'VARIABLES MODELO'!$B$8,'VARIABLES MODELO'!$B$10) -> 833.86 | K16: =I16*J16 -> 1597.8842 | L16: =SUM($K$4:K16) -> 17286.96 | M16: =MROUND(I16*'VARIABLES MODELO'!$B$5,25) -> 75 | N16: =IF(A16<=15,MROUND(M16/'VARIABLES MODELO'!$B$11,0.5),MROUND(M16/'VARIABLES MODELO'!$B$12,0.5)) -> 3 | O16: =IF(A16<=15,SUM($M$4:M16)/'VARIABLES MODELO'!$B$11,SUM($M16:M$19)/'VARIABLES MODELO'!$B$12) -> 29
... A18: 15 | B18: ='VARIABLES MODELO'!$B$4+A18-1 -> 46299 | C18: =IF(A18<=15,"Hiper-Precoz 23%","Precoz 19%") -> Hiper-Precoz 23% | D18: =+D17+E17 -> 55.05 | E18: =HIPER!C20 -> 0.15 | F18: =IF(A18<=5,'VARIABLES MODELO'!$B$13,IF(A18<=15,'VARIABLES MODELO'!$B$14,IF(A18<=50,'VARIABLES MODELO'!$B$15,IF(A18<=80,'VARIABLES MODELO'!$B$16,IF(A18<=120,'VARIABLES MODELO'!$B$17,'VARIABLES MODELO'!$B$18))))) -> 0.035 | G18: =D18*F18 -> 1.92675 | I18: =IF(H18="",G18,H18) -> 1.92675 | J18: =IF(A18<=15,'VARIABLES MODELO'!$B$8,'VARIABLES MODELO'!$B$10) -> 833.86 | K18: =I18*J18 -> 1606.6398 | L18: =SUM($K$4:K18) -> 20495.862 | M18: =MROUND(I18*'VARIABLES MODELO'!$B$5,25) -> 75 | N18: =IF(A18<=15,MROUND(M18/'VARIABLES MODELO'!$B$11,0.5),MROUND(M18/'VARIABLES MODELO'!$B$12,0.5)) -> 3 | O18: =IF(A18<=15,SUM($M$4:M18)/'VARIABLES MODELO'!$B$11,SUM($M18:M$19)/'VARIABLES MODELO'!$B$12) -> 35
A19: 16 | B19: ='VARIABLES MODELO'!$B$4+A19-1 -> 46300 | C19: =IF(A19<=15,"Hiper-Precoz 23%","Precoz 19%") -> Precoz 19% | D19: =+D18+E18 -> 55.2 | E19: =PRECOZ!C6 -> 0.25 | F19: =IF(A19<=5,'VARIABLES MODELO'!$B$13,IF(A19<=15,'VARIABLES MODELO'!$B$14,IF(A19<=50,'VARIABLES MODELO'!$B$15,IF(A19<=80,'VARIABLES MODELO'!$B$16,IF(A19<=120,'VARIABLES MODELO'!$B$17,'VARIABLES MODELO'!$B$18))))) -> 0.032 | G19: =D19*F19 -> 1.7664 | I19: =IF(H19="",G19,H19) -> 1.7664 | J19: =IF(A19<=15,'VARIABLES MODELO'!$B$8,'VARIABLES MODELO'!$B$10) -> 509.36 | K19: =I19*J19 -> 899.7335 | L19: =SUM($K$4:K19) -> 21395.595 | M19: =MROUND(I19*'VARIABLES MODELO'!$B$5,30) -> 60 | N19: =IF(A19<=15,MROUND(M19/'VARIABLES MODELO'!$B$11,0.5),MROUND(M19/'VARIABLES MODELO'!$B$12,0.5)) -> 2 | O19: =IF(A19<=15,SUM($M$4:M19)/'VARIABLES MODELO'!$B$11,SUM($M$19:M19)/'VARIABLES MODELO'!$B$12) -> 2
A20: 17 | B20: ='VARIABLES MODELO'!$B$4+A20-1 -> 46301 | C20: =IF(A20<=15,"Hiper-Precoz 23%","Precoz 19%") -> Precoz 19% | D20: =+D19+E19 -> 55.45 | E20: =PRECOZ!C7 -> 0.25 | F20: =IF(A20<=5,'VARIABLES MODELO'!$B$13,IF(A20<=15,'VARIABLES MODELO'!$B$14,IF(A20<=50,'VARIABLES MODELO'!$B$15,IF(A20<=80,'VARIABLES MODELO'!$B$16,IF(A20<=120,'VARIABLES MODELO'!$B$17,'VARIABLES MODELO'!$B$18))))) -> 0.032 | G20: =D20*F20 -> 1.7744 | I20: =IF(H20="",G20,H20) -> 1.7744 | J20: =IF(A20<=15,'VARIABLES MODELO'!$B$8,'VARIABLES MODELO'!$B$10) -> 509.36 | K20: =I20*J20 -> 903.80838 | L20: =SUM($K$4:K20) -> 22299.404 | M20: =MROUND(I20*'VARIABLES MODELO'!$B$5,30) -> 60 | N20: =IF(A20<=15,MROUND(M20/'VARIABLES MODELO'!$B$11,0.5),MROUND(M20/'VARIABLES MODELO'!$B$12,0.5)) -> 2 | O20: =IF(A20<=15,SUM($M$4:M20)/'VARIABLES MODELO'!$B$11,SUM($M$19:M20)/'VARIABLES MODELO'!$B$12) -> 4
A21: 18 | B21: ='VARIABLES MODELO'!$B$4+A21-1 -> 46302 | C21: =IF(A21<=15,"Hiper-Precoz 23%","Precoz 19%") -> Precoz 19% | D21: =+D20+E20 -> 55.7 | E21: =PRECOZ!C8 -> 0.25 | F21: =IF(A21<=5,'VARIABLES MODELO'!$B$13,IF(A21<=15,'VARIABLES MODELO'!$B$14,IF(A21<=50,'VARIABLES MODELO'!$B$15,IF(A21<=80,'VARIABLES MODELO'!$B$16,IF(A21<=120,'VARIABLES MODELO'!$B$17,'VARIABLES MODELO'!$B$18))))) -> 0.032 | G21: =D21*F21 -> 1.7824 | I21: =IF(H21="",G21,H21) -> 1.7824 | J21: =IF(A21<=15,'VARIABLES MODELO'!$B$8,'VARIABLES MODELO'!$B$10) -> 509.36 | K21: =I21*J21 -> 907.88326 | L21: =SUM($K$4:K21) -> 23207.287 | M21: =MROUND(I21*'VARIABLES MODELO'!$B$5,30) -> 60 | N21: =IF(A21<=15,MROUND(M21/'VARIABLES MODELO'!$B$11,0.5),MROUND(M21/'VARIABLES MODELO'!$B$12,0.5)) -> 2 | O21: =IF(A21<=15,SUM($M$4:M21)/'VARIABLES MODELO'!$B$11,SUM($M$19:M21)/'VARIABLES MODELO'!$B$12) -> 6
A22: 19 | B22: ='VARIABLES MODELO'!$B$4+A22-1 -> 46303 | C22: =IF(A22<=15,"Hiper-Precoz 23%","Precoz 19%") -> Precoz 19% | D22: =+D21+E21 -> 55.95 | E22: =PRECOZ!C9 -> 0.3 | F22: =IF(A22<=5,'VARIABLES MODELO'!$B$13,IF(A22<=15,'VARIABLES MODELO'!$B$14,IF(A22<=50,'VARIABLES MODELO'!$B$15,IF(A22<=80,'VARIABLES MODELO'!$B$16,IF(A22<=120,'VARIABLES MODELO'!$B$17,'VARIABLES MODELO'!$B$18))))) -> 0.032 | G22: =D22*F22 -> 1.7904 | I22: =IF(H22="",G22,H22) -> 1.7904 | J22: =IF(A22<=15,'VARIABLES MODELO'!$B$8,'VARIABLES MODELO'!$B$10) -> 509.36 | K22: =I22*J22 -> 911.95814 | L22: =SUM($K$4:K22) -> 24119.245 | M22: =MROUND(I22*'VARIABLES MODELO'!$B$5,30) -> 60 | N22: =IF(A22<=15,MROUND(M22/'VARIABLES MODELO'!$B$11,0.5),MROUND(M22/'VARIABLES MODELO'!$B$12,0.5)) -> 2 | O22: =IF(A22<=15,SUM($M$4:M22)/'VARIABLES MODELO'!$B$11,SUM($M$19:M22)/'VARIABLES MODELO'!$B$12) -> 8
A23: 20 | B23: ='VARIABLES MODELO'!$B$4+A23-1 -> 46304 | C23: =IF(A23<=15,"Hiper-Precoz 23%","Precoz 19%") -> Precoz 19% | D23: =+D22+E22 -> 56.25 | E23: =PRECOZ!C10 -> 0.3 | F23: =IF(A23<=5,'VARIABLES MODELO'!$B$13,IF(A23<=15,'VARIABLES MODELO'!$B$14,IF(A23<=50,'VARIABLES MODELO'!$B$15,IF(A23<=80,'VARIABLES MODELO'!$B$16,IF(A23<=120,'VARIABLES MODELO'!$B$17,'VARIABLES MODELO'!$B$18))))) -> 0.032 | G23: =D23*F23 -> 1.8 | I23: =IF(H23="",G23,H23) -> 1.8 | J23: =IF(A23<=15,'VARIABLES MODELO'!$B$8,'VARIABLES MODELO'!$B$10) -> 509.36 | K23: =I23*J23 -> 916.848 | L23: =SUM($K$4:K23) -> 25036.093 | M23: =MROUND(I23*'VARIABLES MODELO'!$B$5,30) -> 60 | N23: =IF(A23<=15,MROUND(M23/'VARIABLES MODELO'!$B$11,0.5),MROUND(M23/'VARIABLES MODELO'!$B$12,0.5)) -> 2 | O23: =IF(A23<=15,SUM($M$4:M23)/'VARIABLES MODELO'!$B$11,SUM($M$19:M23)/'VARIABLES MODELO'!$B$12) -> 10
A24: 21 | B24: ='VARIABLES MODELO'!$B$4+A24-1 -> 46305 | C24: =IF(A24<=15,"Hiper-Precoz 23%","Precoz 19%") -> Precoz 19% | D24: =+D23+E23 -> 56.55 | E24: =PRECOZ!C11 -> 0.3 | F24: =IF(A24<=5,'VARIABLES MODELO'!$B$13,IF(A24<=15,'VARIABLES MODELO'!$B$14,IF(A24<=50,'VARIABLES MODELO'!$B$15,IF(A24<=80,'VARIABLES MODELO'!$B$16,IF(A24<=120,'VARIABLES MODELO'!$B$17,'VARIABLES MODELO'!$B$18))))) -> 0.032 | G24: =D24*F24 -> 1.8096 | I24: =IF(H24="",G24,H24) -> 1.8096 | J24: =IF(A24<=15,'VARIABLES MODELO'!$B$8,'VARIABLES MODELO'!$B$10) -> 509.36 | K24: =I24*J24 -> 921.73786 | L24: =SUM($K$4:K24) -> 25957.831 | M24: =MROUND(I24*'VARIABLES MODELO'!$B$5,30) -> 60 | N24: =IF(A24<=15,MROUND(M24/'VARIABLES MODELO'!$B$11,0.5),MROUND(M24/'VARIABLES MODELO'!$B$12,0.5)) -> 2 | O24: =IF(A24<=15,SUM($M$4:M24)/'VARIABLES MODELO'!$B$11,SUM($M$19:M24)/'VARIABLES MODELO'!$B$12) -> 12
A25: 22 | B25: ='VARIABLES MODELO'!$B$4+A25-1 -> 46306 | C25: =IF(A25<=15,"Hiper-Precoz 23%","Precoz 19%") -> Precoz 19% | D25: =+D24+E24 -> 56.85 | E25: =PRECOZ!C12 -> 0.3 | F25: =IF(A25<=5,'VARIABLES MODELO'!$B$13,IF(A25<=15,'VARIABLES MODELO'!$B$14,IF(A25<=50,'VARIABLES MODELO'!$B$15,IF(A25<=80,'VARIABLES MODELO'!$B$16,IF(A25<=120,'VARIABLES MODELO'!$B$17,'VARIABLES MODELO'!$B$18))))) -> 0.032 | G25: =D25*F25 -> 1.8192 | I25: =IF(H25="",G25,H25) -> 1.8192 | J25: =IF(A25<=15,'VARIABLES MODELO'!$B$8,'VARIABLES MODELO'!$B$10) -> 509.36 | K25: =I25*J25 -> 926.62771 | L25: =SUM($K$4:K25) -> 26884.459 | M25: =MROUND(I25*'VARIABLES MODELO'!$B$5,30) -> 60 | N25: =IF(A25<=15,MROUND(M25/'VARIABLES MODELO'!$B$11,0.5),MROUND(M25/'VARIABLES MODELO'!$B$12,0.5)) -> 2 | O25: =IF(A25<=15,SUM($M$4:M25)/'VARIABLES MODELO'!$B$11,SUM($M$19:M25)/'VARIABLES MODELO'!$B$12) -> 14
A26: 23 | B26: ='VARIABLES MODELO'!$B$4+A26-1 -> 46307 | C26: =IF(A26<=15,"Hiper-Precoz 23%","Precoz 19%") -> Precoz 19% | D26: =+D25+E25 -> 57.15 | E26: =PRECOZ!C13 -> 0.3 | F26: =IF(A26<=5,'VARIABLES MODELO'!$B$13,IF(A26<=15,'VARIABLES MODELO'!$B$14,IF(A26<=50,'VARIABLES MODELO'!$B$15,IF(A26<=80,'VARIABLES MODELO'!$B$16,IF(A26<=120,'VARIABLES MODELO'!$B$17,'VARIABLES MODELO'!$B$18))))) -> 0.032 | G26: =D26*F26 -> 1.8288 | I26: =IF(H26="",G26,H26) -> 1.8288 | J26: =IF(A26<=15,'VARIABLES MODELO'!$B$8,'VARIABLES MODELO'!$B$10) -> 509.36 | K26: =I26*J26 -> 931.51757 | L26: =SUM($K$4:K26) -> 27815.976 | M26: =MROUND(I26*'VARIABLES MODELO'!$B$5,30) -> 60 | N26: =IF(A26<=15,MROUND(M26/'VARIABLES MODELO'!$B$11,0.5),MROUND(M26/'VARIABLES MODELO'!$B$12,0.5)) -> 2 | O26: =IF(A26<=15,SUM($M$4:M26)/'VARIABLES MODELO'!$B$11,SUM($M$19:M26)/'VARIABLES MODELO'!$B$12) -> 16
A27: 24 | B27: ='VARIABLES MODELO'!$B$4+A27-1 -> 46308 | C27: =IF(A27<=15,"Hiper-Precoz 23%","Precoz 19%") -> Precoz 19% | D27: =+D26+E26 -> 57.45 | E27: =PRECOZ!C14 -> 0.3 | F27: =IF(A27<=5,'VARIABLES MODELO'!$B$13,IF(A27<=15,'VARIABLES MODELO'!$B$14,IF(A27<=50,'VARIABLES MODELO'!$B$15,IF(A27<=80,'VARIABLES MODELO'!$B$16,IF(A27<=120,'VARIABLES MODELO'!$B$17,'VARIABLES MODELO'!$B$18))))) -> 0.032 | G27: =D27*F27 -> 1.8384 | I27: =IF(H27="",G27,H27) -> 1.8384 | J27: =IF(A27<=15,'VARIABLES MODELO'!$B$8,'VARIABLES MODELO'!$B$10) -> 509.36 | K27: =I27*J27 -> 936.40742 | L27: =SUM($K$4:K27) -> 28752.384 | M27: =MROUND(I27*'VARIABLES MODELO'!$B$5,30) -> 60 | N27: =IF(A27<=15,MROUND(M27/'VARIABLES MODELO'!$B$11,0.5),MROUND(M27/'VARIABLES MODELO'!$B$12,0.5)) -> 2 | O27: =IF(A27<=15,SUM($M$4:M27)/'VARIABLES MODELO'!$B$11,SUM($M$19:M27)/'VARIABLES MODELO'!$B$12) -> 18
A28: 25 | B28: ='VARIABLES MODELO'!$B$4+A28-1 -> 46309 | C28: =IF(A28<=15,"Hiper-Precoz 23%","Precoz 19%") -> Precoz 19% | D28: =+D27+E27 -> 57.75 | E28: =PRECOZ!C15 -> 0.3 | F28: =IF(A28<=5,'VARIABLES MODELO'!$B$13,IF(A28<=15,'VARIABLES MODELO'!$B$14,IF(A28<=50,'VARIABLES MODELO'!$B$15,IF(A28<=80,'VARIABLES MODELO'!$B$16,IF(A28<=120,'VARIABLES MODELO'!$B$17,'VARIABLES MODELO'!$B$18))))) -> 0.032 | G28: =D28*F28 -> 1.848 | I28: =IF(H28="",G28,H28) -> 1.848 | J28: =IF(A28<=15,'VARIABLES MODELO'!$B$8,'VARIABLES MODELO'!$B$10) -> 509.36 | K28: =I28*J28 -> 941.29728 | L28: =SUM($K$4:K28) -> 29693.681 | M28: =MROUND(I28*'VARIABLES MODELO'!$B$5,30) -> 60 | N28: =IF(A28<=15,MROUND(M28/'VARIABLES MODELO'!$B$11,0.5),MROUND(M28/'VARIABLES MODELO'!$B$12,0.5)) -> 2 | O28: =IF(A28<=15,SUM($M$4:M28)/'VARIABLES MODELO'!$B$11,SUM($M$19:M28)/'VARIABLES MODELO'!$B$12) -> 20
A29: 26 | B29: ='VARIABLES MODELO'!$B$4+A29-1 -> 46310 | C29: =IF(A29<=15,"Hiper-Precoz 23%","Precoz 19%") -> Precoz 19% | D29: =+D28+E28 -> 58.05 | E29: =PRECOZ!C16 -> 0.4 | F29: =IF(A29<=5,'VARIABLES MODELO'!$B$13,IF(A29<=15,'VARIABLES MODELO'!$B$14,IF(A29<=50,'VARIABLES MODELO'!$B$15,IF(A29<=80,'VARIABLES MODELO'!$B$16,IF(A29<=120,'VARIABLES MODELO'!$B$17,'VARIABLES MODELO'!$B$18))))) -> 0.032 | G29: =D29*F29 -> 1.8576 | I29: =IF(H29="",G29,H29) -> 1.8576 | J29: =IF(A29<=15,'VARIABLES MODELO'!$B$8,'VARIABLES MODELO'!$B$10) -> 509.36 | K29: =I29*J29 -> 946.18714 | L29: =SUM($K$4:K29) -> 30639.868 | M29: =MROUND(I29*'VARIABLES MODELO'!$B$5,30) -> 60 | N29: =IF(A29<=15,MROUND(M29/'VARIABLES MODELO'!$B$11,0.5),MROUND(M29/'VARIABLES MODELO'!$B$12,0.5)) -> 2 | O29: =IF(A29<=15,SUM($M$4:M29)/'VARIABLES MODELO'!$B$11,SUM($M$19:M29)/'VARIABLES MODELO'!$B$12) -> 22
A30: 27 | B30: ='VARIABLES MODELO'!$B$4+A30-1 -> 46311 | C30: =IF(A30<=15,"Hiper-Precoz 23%","Precoz 19%") -> Precoz 19% | D30: =+D29+E29 -> 58.45 | E30: =PRECOZ!C17 -> 0.4 | F30: =IF(A30<=5,'VARIABLES MODELO'!$B$13,IF(A30<=15,'VARIABLES MODELO'!$B$14,IF(A30<=50,'VARIABLES MODELO'!$B$15,IF(A30<=80,'VARIABLES MODELO'!$B$16,IF(A30<=120,'VARIABLES MODELO'!$B$17,'VARIABLES MODELO'!$B$18))))) -> 0.032 | G30: =D30*F30 -> 1.8704 | I30: =IF(H30="",G30,H30) -> 1.8704 | J30: =IF(A30<=15,'VARIABLES MODELO'!$B$8,'VARIABLES MODELO'!$B$10) -> 509.36 | K30: =I30*J30 -> 952.70694 | L30: =SUM($K$4:K30) -> 31592.575 | M30: =MROUND(I30*'VARIABLES MODELO'!$B$5,30) -> 60 | N30: =IF(A30<=15,MROUND(M30/'VARIABLES MODELO'!$B$11,0.5),MROUND(M30/'VARIABLES MODELO'!$B$12,0.5)) -> 2 | O30: =IF(A30<=15,SUM($M$4:M30)/'VARIABLES MODELO'!$B$11,SUM($M$19:M30)/'VARIABLES MODELO'!$B$12) -> 24
... A153: 150 | B153: ='VARIABLES MODELO'!$B$4+A153-1 -> 46434 | C153: =IF(A153<=15,"Hiper-Precoz 23%","Precoz 19%") -> Precoz 19% | D153: =+D152+E152 -> 132.15 | E153: =PRECOZ!C140 -> 0.7 | F153: =IF(A153<=5,'VARIABLES MODELO'!$B$13,IF(A153<=15,'VARIABLES MODELO'!$B$14,IF(A153<=50,'VARIABLES MODELO'!$B$15,IF(A153<=80,'VARIABLES MODELO'!$B$16,IF(A153<=120,'VARIABLES MODELO'!$B$17,'VARIABLES MODELO'!$B$18))))) -> 0.025 | G153: =D153*F153 -> 3.30375 | I153: =IF(H153="",G153,H153) -> 3.30375 | J153: =IF(A153<=15,'VARIABLES MODELO'!$B$8,'VARIABLES MODELO'!$B$10) -> 509.36 | K153: =I153*J153 -> 1682.7981 | L153: =SUM($K$4:K153) -> 193017.57 | M153: =MROUND(I153*'VARIABLES MODELO'!$B$5,30) -> 120 | N153: =IF(A153<=15,MROUND(M153/'VARIABLES MODELO'!$B$11,0.5),MROUND(M153/'VARIABLES MODELO'!$B$12,0.5)) -> 4 | O153: =IF(A153<=15,SUM($M$4:M153)/'VARIABLES MODELO'!$B$11,SUM($M$19:M153)/'VARIABLES MODELO'!$B$12) -> 363

Sheet CONTROL QUINCENAL
A1: CONTROL QUINCENAL - PESAJE, CONSUMO Y CONVERSIÓN
A3: Control | B3: Día | C3: Fecha | D3: Peso teórico | E3: Peso real | F3: Kg ganados reales | G3: Consumo acum. real/teórico | H3: Índice de Conversión Alimenticia (ICA) Real | I3: Costo acum. | J3: Costo/kg ganado
A4: Q1 | B4: 0 | C4: =+'VARIABLES MODELO'!B4 -> 46285 | D4: =+'VARIABLES MODELO'!B6 -> 55 | F4: =IF(E4="","",E4-'VARIABLES MODELO'!$B$6) | G4: =SUM('MODELO 150D'!$I$4:'MODELO 150D'!I4) -> 1.1 | H4: =IF(F4="","",G4/F4) | I4: ='MODELO 150D'!L14 -> 14095.569 | J4: =IF(F4="","",I4/F4)
A5: Q2 | B5: 15 | C5: ='MODELO 150D'!B18 -> 46299 | D5: ='MODELO 150D'!D18 -> 55.05 | F5: =IF(E5="","",E5-'VARIABLES MODELO'!$B$6) | G5: =SUM('MODELO 150D'!$I$4:'MODELO 150D'!I18) -> 24.5795 | H5: =IF(F5="","",G5/F5) | I5: ='MODELO 150D'!L18 -> 20495.862 | J5: =IF(F5="","",I5/F5)
A6: Q3 | B6: 30 | C6: ='MODELO 150D'!B33 -> 46314 | D6: ='MODELO 150D'!D33 -> 59.65 | F6: =IF(E6="","",E6-'VARIABLES MODELO'!$B$6) | G6: =SUM('MODELO 150D'!$I$4:'MODELO 150D'!I33) -> 52.0531 | H6: =IF(F6="","",G6/F6) | I6: ='MODELO 150D'!L33 -> 34489.815 | J6: =IF(F6="","",I6/F6)
A7: Q4 | B7: 45 | C7: ='MODELO 150D'!B48 -> 46329 | D7: ='MODELO 150D'!D48 -> 65.85 | F7: =IF(E7="","",E7-'VARIABLES MODELO'!$B$6) | G7: =SUM('MODELO 150D'!$I$4:'MODELO 150D'!I48) -> 82.2371 | H7: =IF(F7="","",G7/F7) | I7: ='MODELO 150D'!L48 -> 49864.337 | J7: =IF(F7="","",I7/F7)
A8: Q5 | B8: 60 | C8: ='MODELO 150D'!B63 -> 46344 | D8: ='MODELO 150D'!D63 -> 73.1 | F8: =IF(E8="","",E8-'VARIABLES MODELO'!$B$6) | G8: =SUM('MODELO 150D'!$I$4:'MODELO 150D'!I63) -> 114.2186 | H8: =IF(F8="","",G8/F8) | I8: ='MODELO 150D'!L63 -> 66154.434 | J8: =IF(F8="","",I8/F8)
A9: Q6 | B9: 75 | C9: ='MODELO 150D'!B78 -> 46359 | D9: ='MODELO 150D'!D78 -> 82.1 | F9: =IF(E9="","",E9-'VARIABLES MODELO'!$B$6) | G9: =SUM('MODELO 150D'!$I$4:'MODELO 150D'!I78) -> 149.2736 | H9: =IF(F9="","",G9/F9) | I9: ='MODELO 150D'!L78 -> 84010.049 | J9: =IF(F9="","",I9/F9)
A10: Q7 | B10: 90 | C10: ='MODELO 150D'!B93 -> 46374 | D10: ='MODELO 150D'!D93 -> 91.25 | F10: =IF(E10="","",E10-'VARIABLES MODELO'!$B$6) | G10: =SUM('MODELO 150D'!$I$4:'MODELO 150D'!I93) -> 186.619 | H10: =IF(F10="","",G10/F10) | I10: ='MODELO 150D'!L93 -> 103032.3 | J10: =IF(F10="","",I10/F10)
A11: Q8 | B11: 105 | C11: ='MODELO 150D'!B108 -> 46389 | D11: ='MODELO 150D'!D108 -> 101 | F11: =IF(E11="","",E11-'VARIABLES MODELO'!$B$6) | G11: =SUM('MODELO 150D'!$I$4:'MODELO 150D'!I108) -> 227.128 | H11: =IF(F11="","",G11/F11) | I11: ='MODELO 150D'!L108 -> 123665.97 | J11: =IF(F11="","",I11/F11)
A12: Q9 | B12: 120 | C12: ='MODELO 150D'!B123 -> 46404 | D12: ='MODELO 150D'!D123 -> 111.15 | F12: =IF(E12="","",E12-'VARIABLES MODELO'!$B$6) | G12: =SUM('MODELO 150D'!$I$4:'MODELO 150D'!I123) -> 271.7824 | H12: =IF(F12="","",G12/F12) | I12: ='MODELO 150D'!L123 -> 146411.13 | J12: =IF(F12="","",I12/F12)
A13: Q10 | B13: 135 | C13: ='MODELO 150D'!B138 -> 46419 | D13: ='MODELO 150D'!D138 -> 121.65 | F13: =IF(E13="","",E13-'VARIABLES MODELO'!$B$6) | G13: =SUM('MODELO 150D'!$I$4:'MODELO 150D'!I138) -> 315.56365 | H13: =IF(F13="","",G13/F13) | I13: ='MODELO 150D'!L138 -> 168711.55 | J13: =IF(F13="","",I13/F13)
A14: Q11 | B14: 150 | C14: ='MODELO 150D'!B153 -> 46434 | D14: ='MODELO 150D'!D153 -> 132.15 | F14: =IF(E14="","",E14-'VARIABLES MODELO'!$B$6) | G14: =SUM('MODELO 150D'!$I$4:'MODELO 150D'!I153) -> 363.2824 | H14: =IF(F14="","",G14/F14) | I14: ='MODELO 150D'!L153 -> 193017.57 | J14: =IF(F14="","",I14/F14)

Sheet RESUMEN MEJORADO
A1: RESUMEN ECONÓMICO Y DE CONVERSIÓN - 150 DÍAS
A3: Indicador | B3: Valor | D3: Escenario | E3: Consumo/cab kg | F3: ICA | G3: Costo/cab | H3: Costo/kg ganado
A4: Cantidad terneros | B4: =+'VARIABLES MODELO'!B5 -> 33 | D4: Planilla original | E4: =RESUMEN!G6 -> 376.1825 | F4: =RESUMEN!G6/76.95 -> 4.8886615 | G4: =HIPER!E27+PRECOZ!E148 -> 198262.13 | H4: =(HIPER!E27+PRECOZ!E148)/76.95 -> 2576.506
A5: Peso inicial kg/cab | B5: ='VARIABLES MODELO'!B6 -> 55 | D5: Modelo dinámico | E5: =B10 -> 363.2824 | F5: =B11 -> 4.7087803 | G5: =B14 -> 193017.57 | H5: =B15 -> 2501.848
A6: Peso final teórico kg/cab | B6: =IF('CONTROL QUINCENAL'!E14="",'CONTROL QUINCENAL'!D14,'CONTROL QUINCENAL'!E14) -> 132.15
A7: Kg ganados/cab | B7: =B6-B5 -> 77.15
A8: Consumo Hiper-Precoz kg/cab | B8: =SUM('MODELO 150D'!I4:I18) -> 24.5795 | D8: Nota: el modelo dinámico conserva la curva de peso de la planilla original (55 kg a 132 kg), pero cambia el % de consumo a 2% / 3,5% / 3,2% / 3% / 2,8% / 2,5% del PV. La columna 'Consumo real' del MODELO 150D permite reemplazar el teórico día a día. Alfalfa no se incluye en el costo mientras su precio y consumo permanezcan en 0.
A9: Consumo Precoz kg/cab | B9: =SUM('MODELO 150D'!I19:I153) -> 338.7029
A10: Consumo total kg/cab | B10: =B8+B9 -> 363.2824
A11: ICA (kg alimento/kg ganado) | B11: =B10/B7 -> 4.7087803
A12: Costo Hiper-Precoz $/cab | B12: =SUM('MODELO 150D'!K4:K18) -> 20495.862
A13: Costo Precoz $/cab | B13: =SUM('MODELO 150D'!K19:K153) -> 172521.71
A14: Costo total alimento $/cab | B14: =B12+B13 -> 193017.57
A15: Costo alimento $/kg ganado | B15: =B14/B7 -> 2501.848
A16: Costo total lote ($) - Estimado | B16: =B14*B4 -> 6369579.8
A18: Cantidad de Bolsas Hiper-Precoz (Un) | B18: =MROUND(B8*B4/'VARIABLES MODELO'!B11,1) -> 32
A19: Cantidad de Tn Hiper-Precoz (Tn) | B19: =MROUND(B8*B4/1000,1) -> 1
A20: Cantidad de Bolsas Precoz (Un) | B20: =MROUND(B9*B4/'VARIABLES MODELO'!B12,1) -> 373
A21: Cantidad de Tn Precoz (Tn) | B21: =MROUND(B9*B4/1000,1) -> 11
A22: Valor teórico kg ganados/cab ($) | B22: =B7*'VARIABLES MODELO'!B19 -> 540050
A23: Margen alimento vs kg ganados/cab ($) | B23: =B22-B14 -> 347032.43
A25: Costo del Aimento - Real | B25: =+B19*'VARIABLES MODELO'!B7+'RESUMEN MEJORADO'!B21*'VARIABLES MODELO'!B9 -> 6436820
A26: Valor Total kg ganados/cab ($) | B26: =+B4*B7*'VARIABLES MODELO'!B19 -> 17821650
A28: Resultado de la Operación | B28: =+B26-B25 -> 11384830
A29: Rentabilidad | B29: =+B28/B25 -> 1.7687041
